Workbook

Sheet Dashboard
A1: Professional Bookkeeping Workbook
A2: Business / Account | B2: LUXE TRADING MARKETS (PTY) LTD - Gold Business Account 63130993777
A3: Statements processed | B3: 6
A4: Transactions extracted | B4: 2652
A5: Date range | B5: 2025-01-31 to 2025-08-31
A6: Total money in | B6: =SUM(Transactions!M:M) -> 4087898.4
A7: Total money out | B7: =SUM(Transactions!L:L) -> 4036146.7
A8: Net movement | B8: =B6-B7 -> 51751.69
A9: Transactions flagged for review | B9: =COUNTIF(Transactions!R:R,"Review") -> 16
A10: VAT extracted on bank charges | B10: =SUM(Transactions!Q:Q) -> 239.87
A12: Top Categories | B12: Net
A13: Bank Charges | B13: =SUMIFS(Transactions!N:N,Transactions!I:I,A13) -> -1839
A14: Card / Payment Gateway Receipts | B14: =SUMIFS(Transactions!N:N,Transactions!I:I,A14) -> 886200.57
A15: Customer Receipts | B15: =SUMIFS(Transactions!N:N,Transactions!I:I,A15) -> 2496071.6
A16: Internal Transfers | B16: =SUMIFS(Transactions!N:N,Transactions!I:I,A16) -> -226000
A17: International Payments | B17: =SUMIFS(Transactions!N:N,Transactions!I:I,A17) -> -51438.74
A18: Online Payments | B18: =SUMIFS(Transactions!N:N,Transactions!I:I,A18) -> -100
A19: Other Income | B19: =SUMIFS(Transactions!N:N,Transactions!I:I,A19) -> 235626.18
A20: Other Payments | B20: =SUMIFS(Transactions!N:N,Transactions!I:I,A20) -> -175
A21: Supplier / Payout Payments | B21: =SUMIFS(Transactions!N:N,Transactions!I:I,A21) -> -3286593.9

Sheet Transactions
A1: Txn ID | B1: Date | C1: Month | D1: Statement No | E1: Source File | F1: Page | G1: Description | H1: Counterparty Code | I1: Category | J1: GL Account | K1: Type | L1: Debit | M1: Credit | N1: Net Amount | O1: Running Balance | P1: VAT Rate | Q1: VAT Amount | R1: Review Flag | S1: Accountant Notes
A2: 1 | B2: 45688 | C2: 2025-01 | D2: 2 | E2: GOLD_BUSINESS_ACCOUNT_2.pdf | F2: 1 | G2: AccountFee | I2: Bank Charges | J2: Bank Fees | K2: Debit | L2: 89 | M2: 0 | N2: -89 | O2: 839.82 | P2: 0.15 | Q2: 11.61
A3: 2 | B3: 45691 | C3: 2025-02 | D3: 3 | E3: GOLD_BUSINESS_ACCOUNT_3.pdf | F3: 1 | G3: Int-BankingPmtFrmCu32 | H3: Cu32 | I3: Customer Receipts | J3: Sales Income | K3: Credit | L3: 0 | M3: 10 | N3: 10 | O3: 849.82 | P3: 0 | Q3: 0
A4: 3 | B4: 45695 | C4: 2025-02 | D4: 3 | E4: GOLD_BUSINESS_ACCOUNT_3.pdf | F4: 1 | G4: Int-BankingPmtFrmCu10038 | H4: Cu10038 | I4: Customer Receipts | J4: Sales Income | K4: Credit | L4: 0 | M4: 10 | N4: 10 | O4: 859.82 | P4: 0 | Q4: 0
A5: 4 | B5: 45695 | C5: 2025-02 | D5: 3 | E5: GOLD_BUSINESS_ACCOUNT_3.pdf | F5: 1 | G5: Int-BankingPmtFrmCu10106 | H5: Cu10106 | I5: Customer Receipts | J5: Sales Income | K5: Credit | L5: 0 | M5: 10 | N5: 10 | O5: 869.82 | P5: 0 | Q5: 0
A6: 5 | B6: 45698 | C6: 2025-02 | D6: 3 | E6: GOLD_BUSINESS_ACCOUNT_3.pdf | F6: 1 | G6: Int-BankingPmtFrmCu10122 | H6: Cu10122 | I6: Customer Receipts | J6: Sales Income | K6: Credit | L6: 0 | M6: 10 | N6: 10 | O6: 879.82 | P6: 0 | Q6: 0
A7: 6 | B7: 45700 | C7: 2025-02 | D7: 3 | E7: GOLD_BUSINESS_ACCOUNT_3.pdf | F7: 1 | G7: Int-BankingPmtFrmCu10256 | H7: Cu10256 | I7: Customer Receipts | J7: Sales Income | K7: Credit | L7: 0 | M7: 50 | N7: 50 | O7: 929.82 | P7: 0 | Q7: 0
A8: 7 | B8: 45700 | C8: 2025-02 | D8: 3 | E8: GOLD_BUSINESS_ACCOUNT_3.pdf | F8: 1 | G8: Int-BankingPmtFrmCu10256 | H8: Cu10256 | I8: Customer Receipts | J8: Sales Income | K8: Credit | L8: 0 | M8: 20 | N8: 20 | O8: 949.82 | P8: 0 | Q8: 0
A9: 8 | B9: 45700 | C9: 2025-02 | D9: 3 | E9: GOLD_BUSINESS_ACCOUNT_3.pdf | F9: 1 | G9: Int-BankingPmtFrmCu10256 | H9: Cu10256 | I9: Customer Receipts | J9: Sales Income | K9: Credit | L9: 0 | M9: 100 | N9: 100 | O9: 1049.82 | P9: 0 | Q9: 0
A10: 9 | B10: 45700 | C10: 2025-02 | D10: 3 | E10: GOLD_BUSINESS_ACCOUNT_3.pdf | F10: 1 | G10: Int-BankingPmtFrmCu10265 | H10: Cu10265 | I10: Customer Receipts | J10: Sales Income | K10: Credit | L10: 0 | M10: 5000 | N10: 5000 | O10: 6049.82 | P10: 0 | Q10: 0
A11: 10 | B11: 45700 | C11: 2025-02 | D11: 3 | E11: GOLD_BUSINESS_ACCOUNT_3.pdf | F11: 1 | G11: FNBOBTrfFNBOBTrfInv12/02/2025 | I11: Internal Transfers | J11: Transfers | K11: Credit | L11: 0 | M11: 100000 | N11: 100000 | O11: 106049.82 | P11: 0 | Q11: 0
A12: 11 | B12: 45700 | C12: 2025-02 | D12: 3 | E12: GOLD_BUSINESS_ACCOUNT_3.pdf | F12: 1 | G12: FNBOBPmtFNBOB000000002Cu1 Cu1029254 | H12: Cu1 | I12: Supplier / Payout Payments | J12: Cost of Sales / Supplier Payments | K12: Debit | L12: 33597.72 | M12: 0 | N12: -33597.72 | O12: 72452.1 | P12: 0 | Q12: 0
A13: 12 | B13: 45700 | C13: 2025-02 | D13: 3 | E13: GOLD_BUSINESS_ACCOUNT_3.pdf | F13: 1 | G13: FNBOBPmtFNBOB000000001Cu1 Cu1020733 | H13: Cu1 | I13: Supplier / Payout Payments | J13: Cost of Sales / Supplier Payments | K13: Debit | L13: 137.51 | M13: 0 | N13: -137.51 | O13: 72314.59 | P13: 0 | Q13: 0
A14: 13 | B14: 45701 | C14: 2025-02 | D14: 3 | E14: GOLD_BUSINESS_ACCOUNT_3.pdf | F14: 1 | G14: Int-BankingPmtFrmCu10348 | H14: Cu10348 | I14: Customer Receipts | J14: Sales Income | K14: Credit | L14: 0 | M14: 2000 | N14: 2000 | O14: 74314.59 | P14: 0 | Q14: 0
A15: 14 | B15: 45701 | C15: 2025-02 | D15: 3 | E15: GOLD_BUSINESS_ACCOUNT_3.pdf | F15: 1 | G15: Int-BankingPmtFrmCu10473 | H15: Cu10473 | I15: Customer Receipts | J15: Sales Income | K15: Credit | L15: 0 | M15: 3000 | N15: 3000 | O15: 77314.59 | P15: 0 | Q15: 0
A16: 15 | B16: 45701 | C16: 2025-02 | D16: 3 | E16: GOLD_BUSINESS_ACCOUNT_3.pdf | F16: 1 | G16: Int-BankingPmtFrmCu10348 | H16: Cu10348 | I16: Customer Receipts | J16: Sales Income | K16: Credit | L16: 0 | M16: 3000 | N16: 3000 | O16: 80314.59 | P16: 0 | Q16: 0
A17: 16 | B17: 45701 | C17: 2025-02 | D17: 3 | E17: GOLD_BUSINESS_ACCOUNT_3.pdf | F17: 1 | G17: FNBOBPmtFNBOB000000003Cu1 Cu1034868 | H17: Cu1 | I17: Supplier / Payout Payments | J17: Cost of Sales / Supplier Payments | K17: Debit | L17: 3000 | M17: 0 | N17: -3000 | O17: 77314.59 | P17: 0 | Q17: 0
A18: 17 | B18: 45701 | C18: 2025-02 | D18: 3 | E18: GOLD_BUSINESS_ACCOUNT_3.pdf | F18: 1 | G18: Int-BankingPmtFrmCu10283 | H18: Cu10283 | I18: Customer Receipts | J18: Sales Income | K18: Credit | L18: 0 | M18: 10000 | N18: 10000 | O18: 87314.59 | P18: 0 | Q18: 0
A19: 18 | B19: 45701 | C19: 2025-02 | D19: 3 | E19: GOLD_BUSINESS_ACCOUNT_3.pdf | F19: 1 | G19: Int-BankingPmtFrmCu10130 | H19: Cu10130 | I19: Customer Receipts | J19: Sales Income | K19: Credit | L19: 0 | M19: 9000 | N19: 9000 | O19: 96314.59 | P19: 0 | Q19: 0
A20: 19 | B20: 45701 | C20: 2025-02 | D20: 3 | E20: GOLD_BUSINESS_ACCOUNT_3.pdf | F20: 1 | G20: InternetPmtTo11964250498648 808800266000000008 | I20: Online Payments | J20: Online Payments | K20: Debit | L20: 100 | M20: 0 | N20: -100 | O20: 96214.59 | P20: 0 | Q20: 0
A21: 20 | B21: 45701 | C21: 2025-02 | D21: 3 | E21: GOLD_BUSINESS_ACCOUNT_3.pdf | F21: 1 | G21: Int-BankingPmtFrmCu10130 | H21: Cu10130 | I21: Customer Receipts | J21: Sales Income | K21: Credit | L21: 0 | M21: 20000 | N21: 20000 | O21: 116214.59 | P21: 0 | Q21: 0
A22: 21 | B22: 45701 | C22: 2025-02 | D22: 3 | E22: GOLD_BUSINESS_ACCOUNT_3.pdf | F22: 1 | G22: FNBOBPmtFNBOB000000004Cu1 Cu1043269 | H22: Cu1 | I22: Supplier / Payout Payments | J22: Cost of Sales / Supplier Payments | K22: Debit | L22: 209.33 | M22: 0 | N22: -209.33 | O22: 116005.26 | P22: 0 | Q22: 0
A23: 22 | B23: 45701 | C23: 2025-02 | D23: 3 | E23: GOLD_BUSINESS_ACCOUNT_3.pdf | F23: 1 | G23: FNBOBPmtFNBOB000000005Cu1 Cu1016767 | H23: Cu1 | I23: Supplier / Payout Payments | J23: Cost of Sales / Supplier Payments | K23: Debit | L23: 337.84 | M23: 0 | N23: -337.84 | O23: 115667.42 | P23: 0 | Q23: 0
A24: 23 | B24: 45702 | C24: 2025-02 | D24: 3 | E24: GOLD_BUSINESS_ACCOUNT_3.pdf | F24: 1 | G24: Int-BankingPmtFrmCu10369 | H24: Cu10369 | I24: Customer Receipts | J24: Sales Income | K24: Credit | L24: 0 | M24: 100 | N24: 100 | O24: 115767.42 | P24: 0 | Q24: 0
A25: 24 | B25: 45702 | C25: 2025-02 | D25: 3 | E25: GOLD_BUSINESS_ACCOUNT_3.pdf | F25: 1 | G25: FNBOBPmtFNBOB000000006Cu1 Cu1013076 | H25: Cu1 | I25: Supplier / Payout Payments | J25: Cost of Sales / Supplier Payments | K25: Debit | L25: 41334 | M25: 0 | N25: -41334 | O25: 74433.42 | P25: 0 | Q25: 0
A26: 25 | B26: 45702 | C26: 2025-02 | D26: 3 | E26: GOLD_BUSINESS_ACCOUNT_3.pdf | F26: 1 | G26: FNBOBPmtFNBOB000000007Cu1 Cu1047374 | H26: Cu1 | I26: Supplier / Payout Payments | J26: Cost of Sales / Supplier Payments | K26: Debit | L26: 7000 | M26: 0 | N26: -7000 | O26: 67433.42 | P26: 0 | Q26: 0
A27: 26 | B27: 45702 | C27: 2025-02 | D27: 3 | E27: GOLD_BUSINESS_ACCOUNT_3.pdf | F27: 1 | G27: FNBOBPmtFNBOB000000008Cu1 Cu1043273 | H27: Cu1 | I27: Supplier / Payout Payments | J27: Cost of Sales / Supplier Payments | K27: Debit | L27: 407.54 | M27: 0 | N27: -407.54 | O27: 67025.88 | P27: 0 | Q27: 0
A28: 27 | B28: 45702 | C28: 2025-02 | D28: 3 | E28: GOLD_BUSINESS_ACCOUNT_3.pdf | F28: 2 | G28: Int-BankingPmtFrmCu10141 | H28: Cu10141 | I28: Customer Receipts | J28: Sales Income | K28: Credit | L28: 0 | M28: 200 | N28: 200 | O28: 67225.88 | P28: 0 | Q28: 0
A29: 28 | B29: 45702 | C29: 2025-02 | D29: 3 | E29: GOLD_BUSINESS_ACCOUNT_3.pdf | F29: 2 | G29: Int-BankingPmtFrmCu10502 | H29: Cu10502 | I29: Customer Receipts | J29: Sales Income | K29: Credit | L29: 0 | M29: 300 | N29: 300 | O29: 67525.88 | P29: 0 | Q29: 0
A30: 29 | B30: 45702 | C30: 2025-02 | D30: 3 | E30: GOLD_BUSINESS_ACCOUNT_3.pdf | F30: 2 | G30: Int-BankingPmtFrmCu10141 | H30: Cu10141 | I30: Customer Receipts | J30: Sales Income | K30: Credit | L30: 0 | M30: 100 | N30: 100 | O30: 67625.88 | P30: 0 | Q30: 0
A31: 30 | B31: 45702 | C31: 2025-02 | D31: 3 | E31: GOLD_BUSINESS_ACCOUNT_3.pdf | F31: 2 | G31: Int-BankingPmtFrmCu10141 | H31: Cu10141 | I31: Customer Receipts | J31: Sales Income | K31: Credit | L31: 0 | M31: 200 | N31: 200 | O31: 67825.88 | P31: 0 | Q31: 0
A32: 31 | B32: 45702 | C32: 2025-02 | D32: 3 | E32: GOLD_BUSINESS_ACCOUNT_3.pdf | F32: 2 | G32: Int-BankingPmtFrmCu10587 | H32: Cu10587 | I32: Customer Receipts | J32: Sales Income | K32: Credit | L32: 0 | M32: 10000 | N32: 10000 | O32: 77825.88 | P32: 0 | Q32: 0
... A122: 121 | B122: 45716 | C122: 2025-02 | D122: 3 | E122: GOLD_BUSINESS_ACCOUNT_3.pdf | F122: 3 | G122: FNBOBPmtFNBOB000000033Cu1 Cu10745428 | H122: Cu1 | I122: Supplier / Payout Payments | J122: Cost of Sales / Supplier Payments | K122: Debit | L122: 5504.24 | M122: 0 | N122: -5504.24 | O122: 49484.24 | P122: 0 | Q122: 0
A123: 122 | B123: 45716 | C123: 2025-02 | D123: 3 | E123: GOLD_BUSINESS_ACCOUNT_3.pdf | F123: 3 | G123: ElectronicPaymentsBis/Int1OnTrueTiering 5.00 0.00 | I123: Other Income | J123: Other Income | K123: Credit | L123: 0 | M123: 49484.24 | N123: 49484.24 | O123: 5 | P123: 0 | Q123: 0 | R123: Review
A124: 123 | B124: 45716 | C124: 2025-02 | D124: 3 | E124: GOLD_BUSINESS_ACCOUNT_3.pdf | F124: 3 | G124: AccountFee | I124: Bank Charges | J124: Bank Fees | K124: Debit | L124: 89 | M124: 0 | N124: -89 | O124: 49395.24 | P124: 0.15 | Q124: 11.61
A125: 124 | B125: 45716 | C125: 2025-02 | D125: 3 | E125: GOLD_BUSINESS_ACCOUNT_3.pdf | F125: 3 | G125: Fees | I125: Other Payments | J125: General Expenses | K125: Debit | L125: 5 | M125: 0 | N125: -5 | O125: 49390.24 | P125: 0 | Q125: 0 | R125: Review
A126: 125 | B126: 45717 | C126: 2025-03 | D126: 4 | E126: GOLD_BUSINESS_ACCOUNT_4.pdf | F126: 1 | G126: Int-Banking Pmt Frm Cu11601 | H126: Cu11601 | I126: Customer Receipts | J126: Sales Income | K126: Credit | L126: 0 | M126: 500 | N126: 500 | O126: 49890.24 | P126: 0 | Q126: 0
A127: 126 | B127: 45717 | C127: 2025-03 | D127: 4 | E127: GOLD_BUSINESS_ACCOUNT_4.pdf | F127: 1 | G127: FNB OB Pmt FNB OB 000000045 Cu1 Cu11427 492 | H127: Cu1 | I127: Supplier / Payout Payments | J127: Cost of Sales / Supplier Payments | K127: Debit | L127: 440 | M127: 0 | N127: -440 | O127: 49450.24 | P127: 0 | Q127: 0
A128: 127 | B128: 45717 | C128: 2025-03 | D128: 4 | E128: GOLD_BUSINESS_ACCOUNT_4.pdf | F128: 1 | G128: FNB OB Pmt FNB OB 000000040 Cu1 Cu11470 480 | H128: Cu1 | I128: Supplier / Payout Payments | J128: Cost of Sales / Supplier Payments | K128: Debit | L128: 1182.26 | M128: 0 | N128: -1182.26 | O128: 48267.98 | P128: 0 | Q128: 0
A129: 128 | B129: 45717 | C129: 2025-03 | D129: 4 | E129: GOLD_BUSINESS_ACCOUNT_4.pdf | F129: 1 | G129: FNB OB Pmt FNB OB 000000042 Cu1 Cu10530 481 | H129: Cu1 | I129: Supplier / Payout Payments | J129: Cost of Sales / Supplier Payments | K129: Debit | L129: 1450 | M129: 0 | N129: -1450 | O129: 46817.98 | P129: 0 | Q129: 0
...

Sheet Monthly Summary
A1: Month | B1: Debits | C1: Credits | D1: Net Movement | E1: Transaction Count | F1: Bank Charges | G1: VAT on Bank Charges | H1: Customer Receipts | I1: Supplier Payments
A2: 2025-01 | B2: =SUMIFS(Transactions!$L:$L,Transactions!$C:$C,A2) -> 89 | C2: =SUMIFS(Transactions!$M:$M,Transactions!$C:$C,A2) -> 0 | D2: =C2-B2 -> -89 | E2: =COUNTIFS(Transactions!$C:$C,A2) -> 1 | F2: =SUMIFS(Transactions!$L:$L,Transactions!$C:$C,A2,Transactions!$I:$I,"Bank Charges") -> 89 | G2: =SUMIFS(Transactions!$Q:$Q,Transactions!$C:$C,A2) -> 11.61 | H2: =SUMIFS(Transactions!$M:$M,Transactions!$C:$C,A2,Transactions!$I:$I,"Customer Receipts")+SUMIFS(Transactions!$M:$M,Transactions!$C:$C,A2,Transactions!$I:$I,"Card / Payment Gateway Receipts") -> 0 | I2: =SUMIFS(Transactions!$L:$L,Transactions!$C:$C,A2,Transactions!$I:$I,"Supplier / Payout Payments") -> 0
A3: 2025-02 | B3: =SUMIFS(Transactions!$L:$L,Transactions!$C:$C,A3) -> 290914.58 | C3: =SUMIFS(Transactions!$M:$M,Transactions!$C:$C,A3) -> 388949.24 | D3: =C3-B3 -> 98034.66 | E3: =COUNTIFS(Transactions!$C:$C,A3) -> 123 | F3: =SUMIFS(Transactions!$L:$L,Transactions!$C:$C,A3,Transactions!$I:$I,"Bank Charges") -> 89 | G3: =SUMIFS(Transactions!$Q:$Q,Transactions!$C:$C,A3) -> 11.61 | H3: =SUMIFS(Transactions!$M:$M,Transactions!$C:$C,A3,Transactions!$I:$I,"Customer Receipts")+SUMIFS(Transactions!$M:$M,Transactions!$C:$C,A3,Transactions!$I:$I,"Card / Payment Gateway Receipts") -> 239465 | I3: =SUMIFS(Transactions!$L:$L,Transactions!$C:$C,A3,Transactions!$I:$I,"Supplier / Payout Payments") -> 290720.58
A4: 2025-03 | B4: =SUMIFS(Transactions!$L:$L,Transactions!$C:$C,A4) -> 919668.21 | C4: =SUMIFS(Transactions!$M:$M,Transactions!$C:$C,A4) -> 923115 | D4: =C4-B4 -> 3446.79 | E4: =COUNTIFS(Transactions!$C:$C,A4) -> 508 | F4: =SUMIFS(Transactions!$L:$L,Transactions!$C:$C,A4,Transactions!$I:$I,"Bank Charges") -> 139 | G4: =SUMIFS(Transactions!$Q:$Q,Transactions!$C:$C,A4) -> 18.13 | H4: =SUMIFS(Transactions!$M:$M,Transactions!$C:$C,A4,Transactions!$I:$I,"Customer Receipts")+SUMIFS(Transactions!$M:$M,Transactions!$C:$C,A4,Transactions!$I:$I,"Card / Payment Gateway Receipts") -> 623115 | I4: =SUMIFS(Transactions!$L:$L,Transactions!$C:$C,A4,Transactions!$I:$I,"Supplier / Payout Payments") -> 836657.21
A5: 2025-04 | B5: =SUMIFS(Transactions!$L:$L,Transactions!$C:$C,A5) -> 513921.38 | C5: =SUMIFS(Transactions!$M:$M,Transactions!$C:$C,A5) -> 504908.94 | D5: =C5-B5 -> -9012.44 | E5: =COUNTIFS(Transactions!$C:$C,A5) -> 474 | F5: =SUMIFS(Transactions!$L:$L,Transactions!$C:$C,A5,Transactions!$I:$I,"Bank Charges") -> 579 | G5: =SUMIFS(Transactions!$Q:$Q,Transactions!$C:$C,A5) -> 75.48 | H5: =SUMIFS(Transactions!$M:$M,Transactions!$C:$C,A5,Transactions!$I:$I,"Customer Receipts")+SUMIFS(Transactions!$M:$M,Transactions!$C:$C,A5,Transactions!$I:$I,"Card / Payment Gateway Receipts") -> 500746 | I5: =SUMIFS(Transactions!$L:$L,Transactions!$C:$C,A5,Transactions!$I:$I,"Supplier / Payout Payments") -> 489456.58
A6: 2025-05 | B6: =SUMIFS(Transactions!$L:$L,Transactions!$C:$C,A6) -> 428038.5 | C6: =SUMIFS(Transactions!$M:$M,Transactions!$C:$C,A6) -> 437864 | D6: =C6-B6 -> 9825.5 | E6: =COUNTIFS(Transactions!$C:$C,A6) -> 496 | F6: =SUMIFS(Transactions!$L:$L,Transactions!$C:$C,A6,Transactions!$I:$I,"Bank Charges") -> 100 | G6: =SUMIFS(Transactions!$Q:$Q,Transactions!$C:$C,A6) -> 13.04 | H6: =SUMIFS(Transactions!$M:$M,Transactions!$C:$C,A6,Transactions!$I:$I,"Customer Receipts")+SUMIFS(Transactions!$M:$M,Transactions!$C:$C,A6,Transactions!$I:$I,"Card / Payment Gateway Receipts") -> 437864 | I6: =SUMIFS(Transactions!$L:$L,Transactions!$C:$C,A6,Transactions!$I:$I,"Supplier / Payout Payments") -> 328228.42
A7: 2025-08 | B7: =SUMIFS(Transactions!$L:$L,Transactions!$C:$C,A7) -> 1883515 | C7: =SUMIFS(Transactions!$M:$M,Transactions!$C:$C,A7) -> 1833061.2 | D7: =C7-B7 -> -50453.82 | E7: =COUNTIFS(Transactions!$C:$C,A7) -> 1050 | F7: =SUMIFS(Transactions!$L:$L,Transactions!$C:$C,A7,Transactions!$I:$I,"Bank Charges") -> 843 | G7: =SUMIFS(Transactions!$Q:$Q,Transactions!$C:$C,A7) -> 110 | H7: =SUMIFS(Transactions!$M:$M,Transactions!$C:$C,A7,Transactions!$I:$I,"Customer Receipts")+SUMIFS(Transactions!$M:$M,Transactions!$C:$C,A7,Transactions!$I:$I,"Card / Payment Gateway Receipts") -> 1581082.2 | I7: =SUMIFS(Transactions!$L:$L,Transactions!$C:$C,A7,Transactions!$I:$I,"Supplier / Payout Payments") -> 1341531.2

Sheet Profit & Loss
A1: Category | B1: GL Account | C1: Total Debit | D1: Total Credit | E1: Net | F1: Review Required
A2: Bank Charges | B2: Bank Fees | C2: =SUMIFS(Transactions!$L:$L,Transactions!$I:$I,A2) -> 1839 | D2: =SUMIFS(Transactions!$M:$M,Transactions!$I:$I,A2) -> 0 | E2: =D2-C2 -> -1839 | F2: =IF(OR(A2="Other Income",A2="Other Payments"),"Yes","")
A3: Card / Payment Gateway Receipts | B3: Sales Income | C3: =SUMIFS(Transactions!$L:$L,Transactions!$I:$I,A3) -> 0 | D3: =SUMIFS(Transactions!$M:$M,Transactions!$I:$I,A3) -> 886200.57 | E3: =D3-C3 -> 886200.57 | F3: =IF(OR(A3="Other Income",A3="Other Payments"),"Yes","")
A4: Customer Receipts | B4: Sales Income | C4: =SUMIFS(Transactions!$L:$L,Transactions!$I:$I,A4) -> 0 | D4: =SUMIFS(Transactions!$M:$M,Transactions!$I:$I,A4) -> 2496071.6 | E4: =D4-C4 -> 2496071.6 | F4: =IF(OR(A4="Other Income",A4="Other Payments"),"Yes","")
A5: Internal Transfers | B5: Transfers | C5: =SUMIFS(Transactions!$L:$L,Transactions!$I:$I,A5) -> 696000 | D5: =SUMIFS(Transactions!$M:$M,Transactions!$I:$I,A5) -> 470000 | E5: =D5-C5 -> -226000 | F5: =IF(OR(A5="Other Income",A5="Other Payments"),"Yes","")
A6: International Payments | B6: Foreign Payments | C6: =SUMIFS(Transactions!$L:$L,Transactions!$I:$I,A6) -> 51438.74 | D6: =SUMIFS(Transactions!$M:$M,Transactions!$I:$I,A6) -> 0 | E6: =D6-C6 -> -51438.74 | F6: =IF(OR(A6="Other Income",A6="Other Payments"),"Yes","")
A7: Online Payments | B7: Online Payments | C7: =SUMIFS(Transactions!$L:$L,Transactions!$I:$I,A7) -> 100 | D7: =SUMIFS(Transactions!$M:$M,Transactions!$I:$I,A7) -> 0 | E7: =D7-C7 -> -100 | F7: =IF(OR(A7="Other Income",A7="Other Payments"),"Yes","")
A8: Other Income | B8: Other Income | C8: =SUMIFS(Transactions!$L:$L,Transactions!$I:$I,A8) -> 0 | D8: =SUMIFS(Transactions!$M:$M,Transactions!$I:$I,A8) -> 235626.18 | E8: =D8-C8 -> 235626.18 | F8: =IF(OR(A8="Other Income",A8="Other Payments"),"Yes","") -> Yes
A9: Other Payments | B9: General Expenses | C9: =SUMIFS(Transactions!$L:$L,Transactions!$I:$I,A9) -> 175 | D9: =SUMIFS(Transactions!$M:$M,Transactions!$I:$I,A9) -> 0 | E9: =D9-C9 -> -175 | F9: =IF(OR(A9="Other Income",A9="Other Payments"),"Yes","") -> Yes
A10: Supplier / Payout Payments | B10: Cost of Sales / Supplier Payments | C10: =SUMIFS(Transactions!$L:$L,Transactions!$I:$I,A10) -> 3286593.9 | D10: =SUMIFS(Transactions!$M:$M,Transactions!$I:$I,A10) -> 0 | E10: =D10-C10 -> -3286593.9 | F10: =IF(OR(A10="Other Income",A10="Other Payments"),"Yes","")

Sheet Reconciliation
A1: Bank Reconciliation
A2: Total credits extracted | B2: =SUM(Transactions!M:M) -> 4087898.4
A3: Total debits extracted | B3: =SUM(Transactions!L:L) -> 4036146.7
A4: Net movement | B4: =B2-B3 -> 51751.69
A5: Opening balance (first provided statement) | B5: =_xludf.MINIFS('Source Statements'!C:C,'Source Statements'!C:C,">0") -> #NAME?
A6: Closing balance (last provided statement) | B6: =INDEX('Source Statements'!D:D,MATCH(MAX('Source Statements'!B:B),'Source Statements'!B:B,0)) -> #N/A
A7: Calculated closing balance | B7: =B5+B4 -> #NAME?
A8: Difference | B8: =B6-B7 -> #N/A
A9: Review notes | B9: Difference will not be zero if statement months are missing between uploaded PDFs.

Sheet Category Rules
A1: Category | B1: GL Account | C1: Rule / Source Pattern | D1: Treatment
A2: Customer Receipts | B2: Sales Income | C2: Int-Banking Pmt Frm / Magtape Credit / Payment Cr | D2: Credit / income received
A3: Card / Payment Gateway Receipts | B3: Sales Income | C3: Netcash / Zapper / Flash Mobile | D3: Credit / sales receipts via payment processor
A4: Supplier / Payout Payments | B4: Cost of Sales / Supplier Payments | C4: FNB OB Pmt | D4: Debit / supplier or customer payouts
A5: Internal Transfers | B5: Transfers | C5: FNB OB Trf | D5: Debit/Credit transfer between accounts
A6: Bank Charges | B6: Bank Fees | C6: Account Fee / bank transaction fee / forex fee | D6: Debit / bank charges, VAT extracted where applicable
A7: International Payments | B7: Foreign Payments | C7: Outward Swift | D7: Debit / international or forex-related payment
A8: Online Payments | B8: Online Payments | C8: Internet Pmt To | D8: Debit / online payment
A9: Other Income | B9: Other Income | C9: Unmatched credit | D9: Needs accountant review
A10: Other Payments | B10: General Expenses | C10: Unmatched debit | D10: Needs accountant review

Sheet Source Statements
A1: Source File | B1: Statement No | C1: Opening Balance | D1: Closing Balance | E1: Rows Extracted | F1: First Tx Date | G1: Last Tx Date
A2: GOLD_BUSINESS_ACCOUNT_2.pdf | B2: 2 | C2: 928.82 | D2: 839.82 | E2: 1 | F2: 2025-01-31 | G2: 2025-01-31
A3: GOLD_BUSINESS_ACCOUNT_3.pdf | B3: 3 | C3: 839.82 | D3: 49390.24 | E3: 123 | F3: 2025-02-03 | G3: 2025-02-28
A4: GOLD_BUSINESS_ACCOUNT_4.pdf | B4: 4 | C4: 49390.24 | D4: 52837.03 | E4: 508 | F4: 2025-03-01 | G4: 2025-03-31
A5: GOLD_BUSINESS_ACCOUNT_5.pdf | B5: 5 | C5: 52837.03 | D5: 43824.59 | E5: 474 | F5: 2025-04-01 | G5: 2025-04-30
A6: GOLD_BUSINESS_ACCOUNT_6.pdf | B6: 6 | C6: 43824.59 | D6: 48737.34 | E6: 496 | F6: 2025-05-02 | G6: 2025-05-15
A7: GOLD BUSINESS ACCOUNT 10.pdf | B7: 10 | C7: 50682.69 | D7: 228.87 | E7: 1050 | F7: 2025-08-01 | G7: 2025-08-31
